Workbook

Sheet Hoja1 (2)
B1: EMPLEADO | C1: FECHA DE ALTA
B3: AGISS VELAZQUEZ ALFREDO ALEJANDRO | C3: 0
B4: AGUEDA ALTUZAR JUAN DIEGO | C4: 1
B5: AGUILAR AGUILAR CARLOS ENRIQUE | C5: 30
B6: AGUILAR SOTO ALBERTO ISRAEL | C6: 3
B7: ALBARRAN CRUZ ANA ALEJANDRA | C7: 0
B8: ANGELES MAQUEDA DANIEL ALEJANDRO | C8: 18
B9: ARANA FRAGOSO OBED | C9: 8
B10: ARREDONDO ORTIZ ADRIANA | C10: 1
B11: ATILANO VAZQUEZ MELLADO OCTAVIO | C11: 61
B12: BALLESTEROS ZAMORA JOSE DE JESUS | C12: 0
B13: BAUTISTA MARTINEZ GERMAN EDUARDO | C13: -8
B14: BONILLA LOPEZ GISELA | C14: 9
... B202: ZARCO DOMINGUEZ OSCAR JESUS | C202: 4

Sheet Hoja1
B1: No. | C1: EMPLEADO | D1: FECHA DE ALTA | E1: DIAS TOMADOS
G2: SALDO DE VACACIONES | H2: nomina | I2: correo
B3: 1 | C3: AGISS VELAZQUEZ ALFREDO ALEJANDRO | D3: 2 | E3: 1 | G3: =D3-E3 -> 1 | H3: =VLOOKUP(C3,Hoja2!A:B,2,FALSE) -> 1421164 | I3: =VLOOKUP(C3,Hoja2!A:C,3,FALSE) -> 1a16@asokam.mx
B4: =+B3+1 -> 2 | C4: AGUEDA ALTUZAR JUAN DIEGO | D4: 3 | E4: 2 | G4: =D4-E4 -> 1 | H4: =VLOOKUP(C4,Hoja2!A:B,2,FALSE) -> 1123473 | I4: =VLOOKUP(C4,Hoja2!A:C,3,FALSE) -> 1cm4@construmedika.com
B5: =+B4+1 -> 3 | C5: AGUILAR AGUILAR CARLOS ENRIQUE | D5: 33 | E5: 3 | G5: =D5-E5 -> 30 | H5: =VLOOKUP(C5,Hoja2!A:B,2,FALSE) -> 1525231 | I5: =VLOOKUP(C5,Hoja2!A:C,3,FALSE) -> 2g6@lefarma.com.mx
B6: =+B5+1 -> 4 | C6: AGUILAR SOTO ALBERTO ISRAEL | D6: 3 | G6: =D6-E6 -> 3 | H6: =VLOOKUP(C6,Hoja2!A:B,2,FALSE) -> 1420484 | I6: =VLOOKUP(C6,Hoja2!A:C,3,FALSE) -> 1a14@asokam.mx
B7: =+B6+1 -> 5 | C7: ALBARRAN CRUZ ANA ALEJANDRA | D7: 8 | E7: 8 | G7: =D7-E7 -> 0 | H7: =VLOOKUP(C7,Hoja2!A:B,2,FALSE) -> 1526292 | I7: =VLOOKUP(C7,Hoja2!A:C,3,FALSE) -> 2g22@lefarma.com.mx
B8: =+B7+1 -> 6 | C8: ANGELES MAQUEDA DANIEL ALEJANDRO | D8: 19 | G8: =D8-E8 -> 19 | H8: =VLOOKUP(C8,Hoja2!A:B,2,FALSE) -> 1525230 | I8: =VLOOKUP(C8,Hoja2!A:C,3,FALSE) -> 2g8@lefarma.com.mx
B9: =+B8+1 -> 7 | C9: ARANA FRAGOSO OBED | D9: 10 | E9: 2 | G9: =D9-E9 -> 8 | H9: =VLOOKUP(C9,Hoja2!A:B,2,FALSE) -> 1420154 | I9: =VLOOKUP(C9,Hoja2!A:C,3,FALSE) -> 1a4@asokam.mx
B10: =+B9+1 -> 8 | C10: ARREDONDO ORTIZ ADRIANA | D10: 2 | E10: 1 | G10: =D10-E10 -> 1 | H10: =VLOOKUP(C10,Hoja2!A:B,2,FALSE) -> 1418286 | I10: =VLOOKUP(C10,Hoja2!A:C,3,FALSE) -> 1a41@asokam.mx
B11: =+B10+1 -> 9 | C11: VAZQUEZ MELLADO OCTAVIO ATILANO | D11: 63 | G11: =D11-E11 -> 63 | H11: =VLOOKUP(C11,Hoja2!A:B,2,FALSE) -> 1524228 | I11: =VLOOKUP(C11,Hoja2!A:C,3,FALSE) -> 2g3@lefarma.com.mx | K11: ATILANO VAZQUEZ MELLADO OCTAVIO
B12: =+B11+1 -> 10 | C12: BALLESTEROS ZAMORA JOSE DE JESUS | D12: 0 | G12: =D12-E12 -> 0 | H12: =VLOOKUP(C12,Hoja2!A:B,2,FALSE) -> 1418566 | I12: =VLOOKUP(C12,Hoja2!A:C,3,FALSE) -> 1a901@asokam.mx
B13: =+B12+1 -> 11 | C13: BAUTISTA MARTINEZ GERMAN EDUARDO | D13: -6 | E13: 1 | G13: =D13-E13 -> -7 | H13: =VLOOKUP(C13,Hoja2!A:B,2,FALSE) -> 1418528 | I13: =VLOOKUP(C13,Hoja2!A:C,3,FALSE) -> 1a902@asokam.mx
B14: =+B13+1 -> 12 | C14: BONILLA LOPEZ GISELA | D14: 10 | G14: =D14-E14 -> 10 | H14: =VLOOKUP(C14,Hoja2!A:B,2,FALSE) -> 1528219 | I14: =VLOOKUP(C14,Hoja2!A:C,3,FALSE) -> 2g900@lefarma.com.mx
B15: =+B14+1 -> 13 | C15: CARMONA GARCIA RICARDO FRANCISCO | D15: 129 | G15: =D15-E15 -> 129 | H15: =VLOOKUP(C15,Hoja2!A:B,2,FALSE) -> 1526223 | I15: =VLOOKUP(C15,Hoja2!A:C,3,FALSE) -> 2g4@lefarma.com.mx
B16: =+B15+1 -> 14 | C16: CARMONA MENDOZA ALEXIS RAUL | D16: 0 | G16: =D16-E16 -> 0 | H16: =VLOOKUP(C16,Hoja2!A:B,2,FALSE) -> 1123570 | I16: =VLOOKUP(C16,Hoja2!A:C,3,FALSE) -> 1cm6@construmedika.com
B17: =+B16+1 -> 15 | C17: CASTORENA ANGELES CINTHIA | D17: 23 | G17: =D17-E17 -> 23 | H17: =VLOOKUP(C17,Hoja2!A:B,2,FALSE) -> 1526224 | I17: =VLOOKUP(C17,Hoja2!A:C,3,FALSE) -> 2g13@lefarma.com.mx
B18: =+B17+1 -> 16 | C18: CAZARES GONZALEZ YANET | D18: 6 | G18: =D18-E18 -> 6 | H18: =VLOOKUP(C18,Hoja2!A:B,2,FALSE) -> 1417152 | I18: =VLOOKUP(C18,Hoja2!A:C,3,FALSE) -> 1a26@asokam.mx
B19: =+B18+1 -> 17 | C19: CHAVEZ CERVANTES GABRIELA | D19: -4 | G19: =D19-E19 -> -4 | H19: =VLOOKUP(C19,Hoja2!A:B,2,FALSE) -> 1524389 | I19: =VLOOKUP(C19,Hoja2!A:C,3,FALSE) -> 2g10@lefarma.com.mx
B20: =+B19+1 -> 18 | C20: CORONA CRUZ ALFREDO | D20: -10 | G20: =D20-E20 -> -10 | H20: =VLOOKUP(C20,Hoja2!A:B,2,FALSE) -> 1524227 | I20: =VLOOKUP(C20,Hoja2!A:C,3,FALSE) -> 2g12@lefarma.com.mx
B21: =+B20+1 -> 19 | C21: CRUZ GUERRERO ROBERTO | D21: 0 | G21: =D21-E21 -> 0 | H21: =VLOOKUP(C21,Hoja2!A:B,2,FALSE) -> 1417563 | I21: =VLOOKUP(C21,Hoja2!A:C,3,FALSE) -> 1a37@asokam.mx
B22: =+B21+1 -> 20 | C22: DEL VALLE RUDIÑO MIGUEL ALBERTO | D22: 139 | E22: 3 | G22: =D22-E22 -> 136 | H22: =VLOOKUP(C22,Hoja2!A:B,2,FALSE) -> 1524226 | I22: =VLOOKUP(C22,Hoja2!A:C,3,FALSE) -> 2g9@lefarma.com.mx
B23: =+B22+1 -> 21 | C23: DIAZ SAAVEDRA JORGE MAURICIO | D23: -2 | G23: =D23-E23 -> -2 | H23: =VLOOKUP(C23,Hoja2!A:B,2,FALSE) -> 1417301 | I23: =VLOOKUP(C23,Hoja2!A:C,3,FALSE) -> 1a47@asokam.mx
B24: =+B23+1 -> 22 | C24: DUPEROU LUNA PAULINA | D24: 1 | G24: =D24-E24 -> 1 | H24: =VLOOKUP(C24,Hoja2!A:B,2,FALSE) -> 1526406 | I24: =VLOOKUP(C24,Hoja2!A:C,3,FALSE) -> 2g20@lefarma.com.mx
B25: =+B24+1 -> 23 | C25: ESTRADA SANCHEZ ROYKER JOSE | D25: -3 | G25: =D25-E25 -> -3 | H25: =VLOOKUP(C25,Hoja2!A:B,2,FALSE) -> 1524412 | I25: =VLOOKUP(C25,Hoja2!A:C,3,FALSE) -> 2g21@lefarma.com.mx
B26: =+B25+1 -> 24 | C26: FLORES SANCHEZ VICTOR MANUEL | D26: -1 | E26: 2 | G26: =D26-E26 -> -3 | H26: =VLOOKUP(C26,Hoja2!A:B,2,FALSE) -> 1421163 | I26: =VLOOKUP(C26,Hoja2!A:C,3,FALSE) -> 1a34@asokam.mx
B27: =+B26+1 -> 25 | C27: GARCIA ALONSO CESAR MARTIN | D27: 1 | E27: 2 | G27: =D27-E27 -> -1 | H27: =VLOOKUP(C27,Hoja2!A:B,2,FALSE) -> 1417414 | I27: =VLOOKUP(C27,Hoja2!A:C,3,FALSE) -> 1a12@asokam.mx
B28: =+B27+1 -> 26 | C28: GARCIA GUTIERREZ SANTIAGO | D28: -9 | G28: =D28-E28 -> -9 | H28: =VLOOKUP(C28,Hoja2!A:B,2,FALSE) -> 1417499 | I28: =VLOOKUP(C28,Hoja2!A:C,3,FALSE) -> 1a6@asokam.mx
B29: =+B28+1 -> 27 | C29: GASCA HINOJOSA DANIEL | D29: 13 | G29: =D29-E29 -> 13 | H29: =VLOOKUP(C29,Hoja2!A:B,2,FALSE) -> 1627212 | I29: =VLOOKUP(C29,Hoja2!A:C,3,FALSE) -> 40@grupolefarma.com.mx
B30: =+B29+1 -> 28 | C30: GOMEZ ESQUIVEL ALEJANDRO | D30: 1 | G30: =D30-E30 -> 1 | H30: =VLOOKUP(C30,Hoja2!A:B,2,FALSE) -> 1525232 | I30: =VLOOKUP(C30,Hoja2!A:C,3,FALSE) -> 2g14@lefarma.com.mx
B31: =+B30+1 -> 29 | C31: GONZALEZ BETANZOS VICTOR MANUEL | D31: 5 | E31: 1 | G31: =D31-E31 -> 4 | H31: =VLOOKUP(C31,Hoja2!A:B,2,FALSE) -> 1416466 | I31: =VLOOKUP(C31,Hoja2!A:C,3,FALSE) -> 1a130@asokam.mx
B32: =+B31+1 -> 30 | C32: GUTIERREZ ESPINOSA ADRIANA | D32: 6 | G32: =D32-E32 -> 6 | H32: =VLOOKUP(C32,Hoja2!A:B,2,FALSE) -> 1627181 | I32: =VLOOKUP(C32,Hoja2!A:C,3,FALSE) -> 43@grupolefarma.com.mx
B33: =+B32+1 -> 31 | C33: GUZMAN CASANOVA CARLOS | D33: 8 | G33: =D33-E33 -> 8 | H33: =VLOOKUP(C33,Hoja2!A:B,2,FALSE) -> 1629309 | I33: =VLOOKUP(C33,Hoja2!A:C,3,FALSE) -> 54@grupolefarma.com.mx
B34: =+B33+1 -> 32 | C34: HERNANDEZ CANALES HILDA | D34: -8 | G34: =D34-E34 -> -8 | H34: =VLOOKUP(C34,Hoja2!A:B,2,FALSE) -> 1420155 | I34: =VLOOKUP(C34,Hoja2!A:C,3,FALSE) -> 1a32@asokam.mx
B35: =+B34+1 -> 33 | C35: HERNANDEZ GONZALEZ MARIA DEL CARMEN | D35: 0 | G35: =D35-E35 -> 0 | H35: =VLOOKUP(C35,Hoja2!A:B,2,FALSE) -> 1420549 | I35: =VLOOKUP(C35,Hoja2!A:C,3,FALSE) -> 1a17@asokam.mx
B36: =+B35+1 -> 34 | C36: HERNANDEZ ROSALES MARIA DE LOS ANGELES | D36: 139 | G36: =D36-E36 -> 139 | H36: =VLOOKUP(C36,Hoja2!A:B,2,FALSE) -> 1422148 | I36: =VLOOKUP(C36,Hoja2!A:C,3,FALSE) -> 5@grupolefarma.com.mx
B37: =+B36+1 -> 35 | C37: HIDALGO AYANEGUI ADRIAN | D37: -1 | G37: =D37-E37 -> -1 | H37: =VLOOKUP(C37,Hoja2!A:B,2,FALSE) -> 1418544 | I37: =VLOOKUP(C37,Hoja2!A:C,3,FALSE) -> 1a904@asokam.mx
B38: =+B37+1 -> 36 | C38: HIPOLITO OSORIO SUSANA | D38: 8 | G38: =D38-E38 -> 8 | H38: =VLOOKUP(C38,Hoja2!A:B,2,FALSE) -> 1528220 | I38: =VLOOKUP(C38,Hoja2!A:C,3,FALSE) -> 2g901@lefarma.com.mx
B39: =+B38+1 -> 37 | C39: HUERTA GARCIA JOSE RICARDO | D39: -4 | G39: =D39-E39 -> -4 | H39: =VLOOKUP(C39,Hoja2!A:B,2,FALSE) -> 1528247 | I39: =VLOOKUP(C39,Hoja2!A:C,3,FALSE) -> 1a11@asokam.mx
B40: =+B39+1 -> 38 | C40: JIMENEZ GIL BERENICE | D40: 2 | E40: 1 | G40: =D40-E40 -> 1 | H40: =VLOOKUP(C40,Hoja2!A:B,2,FALSE) -> 1429483 | I40: =VLOOKUP(C40,Hoja2!A:C,3,FALSE) -> 19@grupolefarma.com.mx
...

Sheet Hoja2
A1: (No column name) | B1: nomina | C1: correo
A2: CORTES MEJIA NOE | B2: 1629200 | C2: 7@grupolefarma.com.mx
A3: CAZARES GONZALEZ YANET | B3: 1417152 | C3: 1a26@asokam.mx
A4: ZENDEJAS ARAIZA LESLY ISAMAR | B4: 1418177 | C4: 1a25@asokam.mx
A5: TORIJA NIETO ROBERTO | B5: 1419172 | C5: 1a129@asokam.mx
A6: POZO URQUIZO LUIS ANTONIO | B6: 1422149 | C6: 1a1@asokam.mx
A7: LOPEZ PEREZ EMMANUEL | B7: 1422153 | C7: 1a42@asokam.mx
A8: SANTANA ALCANTARA ERIK | B8: 1422180 | C8: 33@grupolefarma.com.mx
A9: ROJAS GUERRA OLGA | B9: 1428179 | C9: 1a900@asokam.mx
A10: GUTIERREZ ESPINOSA ADRIANA | B10: 1627181 | C10: 43@grupolefarma.com.mx
A11: GASCA HINOJOSA DANIEL | B11: 1627212 | C11: 40@grupolefarma.com.mx
A12: HERNANDEZ ROSALES MARIA DE LOS ANGELES | B12: 1422148 | C12: 5@grupolefarma.com.mx
A13: VELAZQUEZ VILLEGAS DANIEL WILFRIDO | B13: 1127216 | C13: 26@grupolefarma.com.mx
... A209: MENDEZ HERNANDEZ LILIA ITZEL | B209: 1420589 | C209: NULL
